<?xml version="1.0"?>
<robot name="robot">
	<link name="base_link">

		<visual>
			<origin rpy="0 0 0" xyz="0 0 0"/>
			<geometry>
				<cylinder length="0.005" radius="0.13"/>
			</geometry>
			<material name="white">
				<color rgba="1 1 1 1"/>
			</material>
		</visual>

		<collision>
			<origin rpy="0 0 0" xyz="0 0 0"/>
			<geometry>
				<cylinder length="0.005" radius="0.13"/>
			</geometry>
		</collision>
	</link>

	<link name="left_motor">
		<visual>
			<origin rpy="1.5707 0 0" xyz="0 0 0"/>
			<geometry>
				<cylinder length="0.06" radius="0.02"/>
			</geometry>
			<material name="gray">
				<color rgba="0.75 0.75 0.75 1"/>
			</material>
		</visual>
	</link>

	<joint name="base_link_to_left_motor" type="fixed">
		<origin xyz="0 0.055 -0.035" rpy="0 0 0"/>
		<parent link="base_link"/>
		<child link="left_motor"/>
	</joint>

	<link name="left_wheel">
		<visual>
			<origin rpy="1.5707 0 0" xyz="0 0 0"/>
			<geometry>
				<cylinder length="0.03" radius="0.03"/>
			</geometry>
			<material name="gray">
				<color rgba="0.75 0.75 0.75 1"/>
			</material>
		</visual>
		<collision>
			<origin rpy="1.57079632679 0 0 " xyz="0 0 0"/>
			<geometry>
				<cylinder length="0.03" radius="0.03"/>
			</geometry>
		</collision>
		<inertial>
			<mass value="2.5"/>
			<origin xyz="0 0 0"/>
			<inertia ixx="0.00108333333333" ixy="0" ixz="0" iyy="0.00108333333333" iyz="0" izz="0.002"/>
		</inertial>
	</link>
	<gazebo reference="left_wheel">
		<mu1 value="1.0"/>
		<mu2 value="1.0"/>
		<kp value="10000000.0"/>
		<kd value="1.0"/>
		<fdir1 value="1 0 0"/>
		<material>Gazebo/Grey</material>
		<turnGravityOff>false</turnGravityOff>
	</gazebo>
	<joint name="left_motor_to_left_wheel" type="continuous">
		<origin xyz="0 0.1 -0.035" rpy="0 0 0"/>
		<parent link="base_link"/>
		<child link="left_wheel"/>
		<axis xyz="0 1 0"/>
	</joint>
	<transmission name="simple_trans_left">
		<type>transmission_interface/SimpleTransmission</type>

		<joint name="left_motor_to_left_wheel" />

		<acturtor name="foo_motor">
			<mechanicalReduction>50</mechanicalReduction>
			<hardwareInterface>VelocityJointInterface</hardwareInterface>
		</acturtor>
	</transmission>

	<link name="left_fix">
		<visual>
			<origin rpy="0 0 0" xyz="0 0 0"/>
			<geometry>
				<box size="0.05 0.005 -0.0325"/>
			</geometry>
			<material name="gray">
				<color rgba="0.75 0.75 0.75 1"/>
			</material>
		</visual>
	</link>

	<joint name="left_fix_to_base_link" type="fixed">
		<origin xyz="0 0.0225 -0.01875" rpy="0 0 0"/>
		<parent link="base_link"/>
		<child link="left_fix"/>
	</joint>

	<link name="left_fix2">
		<visual>
			<origin rpy="0 0 0" xyz="0 0 0"/>
			<geometry>
				<cylinder length="0.005" radius="0.025"/>
			</geometry>
			<material name="gray">
				<color rgba="0.75 0.75 0.75 1"/>
			</material>
		</visual>
	</link>

	<joint name="left_fix2_to_left_fix" type="fixed">
		<origin xyz="0 0 -0.01625" rpy="1.5707 0 0"/>
		<parent link="left_fix"/>
		<child link="left_fix2"/>
	</joint>

	<link name="left_fix3">
		<visual>
			<origin rpy="0 0 0" xyz="0 0 0"/>
			<geometry>
				<box size="0.05 0.005 -0.0325"/>
			</geometry>
			<material name="gray">
				<color rgba="0.75 0.75 0.75 1"/>
			</material>
		</visual>
	</link>

	<joint name="left_fix3_to_base_link" type="fixed">
		<origin xyz="0 0.0825 -0.01875" rpy="0 0 0"/>
		<parent link="base_link"/>
		<child link="left_fix3"/>
	</joint>

	<link name="left_fix4">
		<visual>
			<origin rpy="0 0 0" xyz="0 0 0"/>
			<geometry>
				<cylinder length="0.005" radius="0.025"/>
			</geometry>
			<material name="gray">
				<color rgba="0.75 0.75 0.75 1"/>
			</material>
		</visual>
	</link>

	<joint name="left_fix4_to_left_fix3" type="fixed">
		<origin xyz="0 0 -0.01625" rpy="1.5707 0 0"/>
		<parent link="left_fix3"/>
		<child link="left_fix4"/>
	</joint>






	<link name="right_motor">
		<visual>
			<origin rpy="1.5707 0 0" xyz="0 0 0"/>
			<geometry>
				<cylinder length="0.06" radius="0.02"/>
			</geometry>
			<material name="gray">
				<color rgba="0.75 0.75 0.75 1"/>
			</material>
		</visual>
	</link>

	<joint name="base_link_to_right_motor" type="fixed">
		<origin xyz="0 -0.055 -0.035" rpy="0 0 0"/>
		<parent link="base_link"/>
		<child link="right_motor"/>
	</joint>

	<link name="right_wheel">
		<visual>
			<origin rpy="1.5707 0 0" xyz="0 0 0"/>
			<geometry>
				<cylinder length="0.03" radius="0.03"/>
			</geometry>
			<material name="gray">
				<color rgba="0.75 0.75 0.75 1"/>
			</material>
		</visual>
		<collision>
			<origin rpy="1.57079632679 0 0 " xyz="0 0 0"/>
			<geometry>
				<cylinder length="0.03" radius="0.03"/>
			</geometry>
		</collision>
		<inertial>
			<mass value="2.5"/>
			<origin xyz="0 0 0"/>
			<inertia ixx="0.00108333333333" ixy="0" ixz="0" iyy="0.00108333333333" iyz="0" izz="0.002"/>
		</inertial>
	</link>
	<gazebo reference="right_wheel">
		<mu1 value="1.0"/>
		<mu2 value="1.0"/>
		<kp value="10000000.0"/>
		<kd value="1.0"/>
		<fdir1 value="1 0 0"/>
		<material>Gazebo/Grey</material>
		<turnGravityOff>false</turnGravityOff>
	</gazebo>
	<joint name="right_motor_to_right_wheel" type="continuous">
		<origin xyz="0 -0.1 -0.035" rpy="0 0 0"/>
		<parent link="base_link"/>
		<child link="right_wheel"/>
		<axis xyz="0 1 0"/>
	</joint>


	<link name="right_fix">
		<visual>
			<origin rpy="0 0 0" xyz="0 0 0"/>
			<geometry>
				<box size="0.05 0.005 -0.0325"/>
			</geometry>
			<material name="gray">
				<color rgba="0.75 0.75 0.75 1"/>
			</material>
		</visual>
	</link>

	<joint name="right_fix_to_base_link" type="fixed">
		<origin xyz="0 -0.0225 -0.01875" rpy="0 0 0"/>
		<parent link="base_link"/>
		<child link="right_fix"/>
	</joint>

	<link name="right_fix2">
		<visual>
			<origin rpy="0 0 0" xyz="0 0 0"/>
			<geometry>
				<cylinder length="0.005" radius="0.025"/>
			</geometry>
			<material name="gray">
				<color rgba="0.75 0.75 0.75 1"/>
			</material>
		</visual>
	</link>

	<joint name="right_fix2_to_right_fix" type="fixed">
		<origin xyz="0 0 -0.01625" rpy="1.5707 0 0"/>
		<parent link="right_fix"/>
		<child link="right_fix2"/>
	</joint>

	<link name="right_fix3">
		<visual>
			<origin rpy="0 0 0" xyz="0 0 0"/>
			<geometry>
				<box size="0.05 0.005 -0.0325"/>
			</geometry>
			<material name="gray">
				<color rgba="0.75 0.75 0.75 1"/>
			</material>
		</visual>
	</link>

	<joint name="right_fix3_to_base_link" type="fixed">
		<origin xyz="0 -0.0825 -0.01875" rpy="0 0 0"/>
		<parent link="base_link"/>
		<child link="right_fix3"/>
	</joint>

	<link name="right_fix4">
		<visual>
			<origin rpy="0 0 0" xyz="0 0 0"/>
			<geometry>
				<cylinder length="0.005" radius="0.025"/>
			</geometry>
			<material name="gray">
				<color rgba="0.75 0.75 0.75 1"/>
			</material>
		</visual>
	</link>

	<joint name="right_fix4_to_right_fix3" type="fixed">
		<origin xyz="0 0 -0.01625" rpy="1.5707 0 0"/>
		<parent link="right_fix3"/>
		<child link="right_fix4"/>
	</joint>

	<link name="forward_wheel_base">
		<visual>
			<origin rpy="0 0 0" xyz="0 0 0"/>
			<geometry>
				<box size="0.05 0.05 0.0325"/>
			</geometry>
			<material name="black">
				<color rgba="0 0 0 1"/>
			</material>
		</visual>
		<collision>
			<origin rpy="1.57079632679 0 0 " xyz="0 0 0"/>
			<geometry>
				<cylinder length="0.03" radius="0.032"/>
			</geometry>
		</collision>
		<inertial>
			<mass value="2.5"/>
			<origin xyz="0 0 0"/>
			<inertia ixx="0.00108333333333" ixy="0" ixz="0" iyy="0.00108333333333" iyz="0" izz="0.002"/>
		</inertial>
	</link>

	<joint name="forward_wheel_to_base_link" type="fixed">
		<origin xyz="0.08 0 -0.01875" rpy="0 0 0"/>
		<parent link="base_link"/>
		<child link="forward_wheel_base"/>
	</joint>

	<link name="forward_wheel">
		<visual>
			<origin rpy="0 0 0" xyz="0 0 0"/>
			<geometry>
				<sphere radius="0.03"/>
			</geometry>
			<material name="white">
				<color rgba="1 1 1 1"/>
			</material>
		</visual>
		<collision>
			<origin xyz="0 0 0" rpy="0 0 0"/>
			<geometry>
				<sphere radius="0.03"/>
			</geometry>
		</collision>
		<inertial>
			<mass value="2.5"/>
			<origin xyz="0 0 0"/>
			<inertia ixx="0.00108333333333" ixy="0" ixz="0" iyy="0.00108333333333" iyz="0" izz="0.002"/>
		</inertial>
	</link>

	<joint name="forward_wheel_to_forward_wheel_base" type="fixed">
		<origin xyz="0 0 -0.01625" rpy="0 0 0"/>
		<parent link="forward_wheel_base"/>
		<child link="forward_wheel"/>
	</joint>

	<link name="back_wheel_base">
		<visual>
			<origin rpy="0 0 0" xyz="0 0 0"/>
			<geometry>
				<box size="0.05 0.05 0.0325"/>
			</geometry>
			<material name="black">
				<color rgba="0 0 0 1"/>
			</material>
		</visual>
	</link>

	<joint name="back_wheel_to_base_link" type="fixed">
		<origin xyz="-0.08 0 -0.01875" rpy="0 0 0"/>
		<parent link="base_link"/>
		<child link="back_wheel_base"/>
	</joint>

	<link name="back_wheel">
		<visual>
			<origin rpy="0 0 0" xyz="0 0 0"/>
			<geometry>
				<sphere radius="0.03"/>
			</geometry>
			<material name="white">
				<color rgba="1 1 1 1"/>
			</material>
		</visual>
		<collision>
			<origin xyz="0 0 0" rpy="0 0 0"/>
			<geometry>
				<sphere radius="0.03"/>
			</geometry>
		</collision>
		<inertial>
			<mass value="2.5"/>
			<origin xyz="0 0 0"/>
			<inertia ixx="0.00108333333333" ixy="0" ixz="0" iyy="0.00108333333333" iyz="0" izz="0.002"/>
		</inertial>
	</link>

	<joint name="back_wheel_to_back_wheel_base" type="fixed">
		<origin xyz="0 0 -0.01625" rpy="0 0 0"/>
		<parent link="back_wheel_base"/>
		<child link="back_wheel"/>
	</joint>









	<link name="second_base">
		<visual>
			<origin rpy="0 0 0" xyz="0 0 0.07"/>
			<geometry>
				<cylinder length="0.005" radius="0.13"/>
			</geometry>
			<material name="white">
				<color rgba="1 1 1 1"/>
			</material>
		</visual>
	</link>

	<joint name="second_base_to_base_link" type="fixed">
		<origin xyz="0 0 0" rpy="0 0 0"/>
		<parent link="base_link"/>
		<child link="second_base"/>
	</joint>

	<link name="second_link1">
		<visual>
			<origin rpy="0 0 0" xyz="0.08 0.08 0.035"/>
			<geometry>
				<cylinder length="0.065" radius="0.003"/>
			</geometry>
			<material name="black">
				<color rgba="0 0 0 1"/>
			</material>
		</visual>
	</link>

	<joint name="second_link1_to_second_link" type="fixed">
		<origin xyz="0 0 0" rpy="0 0 0"/>
		<parent link="second_base"/>
		<child link="second_link1"/>
	</joint>

	<link name="second_link2">
		<visual>
			<origin rpy="0 0 0" xyz="-0.08 0.08 0.035"/>
			<geometry>
				<cylinder length="0.065" radius="0.003"/>
			</geometry>
			<material name="black">
				<color rgba="0 0 0 1"/>
			</material>
		</visual>
	</link>

	<joint name="second_link2_to_second_link" type="fixed">
		<origin xyz="0 0 0" rpy="0 0 0"/>
		<parent link="second_base"/>
		<child link="second_link2"/>
	</joint>

	<link name="second_link3">
		<visual>
			<origin rpy="0 0 0" xyz="-0.08 -0.08 0.035"/>
			<geometry>
				<cylinder length="0.065" radius="0.003"/>
			</geometry>
			<material name="black">
				<color rgba="0 0 0 1"/>
			</material>
		</visual>
	</link>

	<joint name="second_link3_to_second_link" type="fixed">
		<origin xyz="0 0 0" rpy="0 0 0"/>
		<parent link="second_base"/>
		<child link="second_link3"/>
	</joint>

	<link name="second_link4">
		<visual>
			<origin rpy="0 0 0" xyz="0.08 -0.08 0.035"/>
			<geometry>
				<cylinder length="0.065" radius="0.003"/>
			</geometry>
			<material name="black">
				<color rgba="0 0 0 1"/>
			</material>
		</visual>
	</link>

	<joint name="second_link4_to_second_link" type="fixed">
		<origin xyz="0 0 0" rpy="0 0 0"/>
		<parent link="second_base"/>
		<child link="second_link4"/>
	</joint>









	<link name="third_base">
		<visual>
			<origin rpy="0 0 0" xyz="0 0 0.14"/>
			<geometry>
				<cylinder length="0.005" radius="0.13"/>
			</geometry>
			<material name="white">
				<color rgba="1 1 1 1"/>
			</material>
		</visual>
	</link>

	<joint name="third_base_to_base_link" type="fixed">
		<origin xyz="0 0 0" rpy="0 0 0"/>
		<parent link="base_link"/>
		<child link="third_base"/>
	</joint>

	<link name="third_link1">
		<visual>
			<origin rpy="0 0 0" xyz="0.08 0.08 0.105"/>
			<geometry>
				<cylinder length="0.065" radius="0.003"/>
			</geometry>
			<material name="black">
				<color rgba="0 0 0 1"/>
			</material>
		</visual>
	</link>

	<joint name="third_link1_to_third_link" type="fixed">
		<origin xyz="0 0 0" rpy="0 0 0"/>
		<parent link="third_base"/>
		<child link="third_link1"/>
	</joint>

	<link name="third_link2">
		<visual>
			<origin rpy="0 0 0" xyz="-0.08 0.08 0.105"/>
			<geometry>
				<cylinder length="0.065" radius="0.003"/>
			</geometry>
			<material name="black">
				<color rgba="0 0 0 1"/>
			</material>
		</visual>
	</link>

	<joint name="third_link2_to_third_link" type="fixed">
		<origin xyz="0 0 0" rpy="0 0 0"/>
		<parent link="third_base"/>
		<child link="third_link2"/>
	</joint>

	<link name="third_link3">
		<visual>
			<origin rpy="0 0 0" xyz="-0.08 -0.08 0.105"/>
			<geometry>
				<cylinder length="0.065" radius="0.003"/>
			</geometry>
			<material name="black">
				<color rgba="0 0 0 1"/>
			</material>
		</visual>
	</link>

	<joint name="third_link3_to_third_link" type="fixed">
		<origin xyz="0 0 0" rpy="0 0 0"/>
		<parent link="third_base"/>
		<child link="third_link3"/>
	</joint>

	<link name="third_link4">
		<visual>
			<origin rpy="0 0 0" xyz="0.08 -0.08 0.105"/>
			<geometry>
				<cylinder length="0.065" radius="0.003"/>
			</geometry>
			<material name="black">
				<color rgba="0 0 0 1"/>
			</material>
		</visual>
	</link>

	<joint name="third_link4_to_third_link" type="fixed">
		<origin xyz="0 0 0" rpy="0 0 0"/>
		<parent link="third_base"/>
		<child link="third_link4"/>
	</joint>

	<!-- depth camera -->
	<link name="camera_front_link">
		<visual>
			<origin xyz="0 0 0" rpy="1.57 0 1.57"/>
			<geometry>
				<!-- <box size="${d435_cam_width} ${d435_cam_height} ${d435_cam_depth}"/> -->
				<mesh filename="package://autonomus_transport_industrial_system/urdf/meshes/d435.dae" />
				<!--<mesh filename="package://realsense2_description/meshes/d435/d435.dae" />-->

			</geometry>
			<material name="Blue"/>
		</visual>
	</link>
	<joint name="camera_front_joint" type="fixed">
		<origin rpy="0.0 0.15 0" xyz="0.06 0.0 0.10"/>
		<parent link="base_link"/>
		<child link="camera_front_link"/>
	</joint>
	<gazebo reference="camera_front_link">
		<sensor name="camera_link_front" type="depth">
			<update_rate>20</update_rate>
			<camera>
				<horizontal_fov>1.047198</horizontal_fov>
				<image>
					<width>1920</width>
					<height>480</height>
					<format>R8G8B8</format>
				</image>
				<clip>
					<near>0.02</near>
					<far>300</far>
				</clip>
			</camera>
			<plugin name="camera_link_controller" filename="libgazebo_ros_openni_kinect.so">
				<baseline>0.2</baseline>
				<alwaysOn>true</alwaysOn>
				<updateRate>0.0</updateRate>

				<cameraName>kinect_alpha</cameraName>
				<imageTopicName>/rgb/image_raw </imageTopicName>
				<cameraInfoTopicName>/rgb/camera_info</cameraInfoTopicName>
				<depthImageTopicName>/depth/image_raw</depthImageTopicName>
				<depthImageInfoTopicName>/depth/camera_info</depthImageInfoTopicName>
				<pointCloudTopicName>/depth/points</pointCloudTopicName>
				<frameName>camera_front</frameName>
				<pointCloudCutoff>0.5</pointCloudCutoff>
				<pointCloudCutoffMax>3.0</pointCloudCutoffMax>
				<distortionK1>0.00000001</distortionK1>
				<distortionK2>0.00000001</distortionK2>
				<distortionK3>0.00000001</distortionK3>
				<distortionT1>0.00000001</distortionT1>
				<distortionT2>0.00000001</distortionT2>
				<CxPrime>0</CxPrime>
				<Cx>0</Cx>
				<Cy>0</Cy>
				<focalLength>0</focalLength>
				<hackBaseline>0</hackBaseline>
			</plugin>
		</sensor>
	</gazebo>

	<!-- imu sensor -->
	<link name="imu_link">
		<visual>
			<origin xyz="0 0 0" rpy="0 0 0"/>
			<geometry>
				<box size="0.05 0.05 0.0325"/>
			</geometry>
			<material name="Blue"/>
		</visual>
	</link>
	<joint name="imu_joint" type="fixed">
		<origin rpy="0.0 0 0" xyz="0.0 0.0 0.1"/>
		<parent link="base_link"/>
		<child link="imu_link"/>
	</joint>
	<gazebo reference="imu_link">
		<gravity>true</gravity>
		<sensor name="imu_sensor" type="imu">
			<always_on>true</always_on>
			<update_rate>100</update_rate>
			<visualize>true</visualize>
			<topic>imu</topic>
			<plugin filename="libgazebo_ros_imu_sensor.so" name="imu_plugin">
				<topicName>imu</topicName>
				<bodyName>imu_link</bodyName>
				<updateRateHZ>10.0</updateRateHZ>
				<gaussianNoise>0.0</gaussianNoise>
				<xyzOffset>0 0 0</xyzOffset>
				<rpyOffset>0 0 0</rpyOffset>
				<frameName>imu_link</frameName>
				<initialOrientationAsReference>false</initialOrientationAsReference>
			</plugin>
			<pose>0 0 0 0 0 0</pose>
		</sensor>
	</gazebo>

	<!-- Hokuyo Laser -->
	<joint name="hokuyo_joint" type="fixed">
		<axis xyz="0 1 0" />
		<origin xyz="0.06 0 0.03" rpy="0 0 -3.14"/>
		<parent link="base_link"/>
		<child link="hokuyo_link"/>
	</joint>

	<link name="hokuyo_link">
		<collision>
			<origin xyz="0 0 0" rpy="0 0 0"/>
			<geometry>
				<box size=".05 .05 .05"/>
			</geometry>
		</collision>

		<visual>
			<origin xyz="0 0 0" rpy="0 0 0"/>
			<geometry>
				<mesh filename="package://autonomus_transport_industrial_system/urdf/meshes/hokuyo.dae"/>
			</geometry>
		</visual>

		<inertial>
			<mass value="1e-5" />
			<origin xyz="0 0 0" rpy="0 0 0"/>
			<inertia ixx="1e-6" ixy="0" ixz="0" iyy="1e-6" iyz="0" izz="1e-6" />
		</inertial>
	</link>
	<gazebo>
		<plugin name="object_controller" filename="libgazebo_ros_planar_move.so">
			<commandTopic>cmd_vel</commandTopic>
			<odometryTopic>odom</odometryTopic>
			<odometryFrame>odom</odometryFrame>
			<!-- <odometryRate>20.0</odometryRate> -->
			<broadcastTF>false</broadcastTF>
			<publishOdomTF>false</publishOdomTF>
			<robotBaseFrame>base_link</robotBaseFrame>
		</plugin>
	</gazebo>

	<!-- hokuyo laser sensor-->
	<gazebo reference="hokuyo_link">
		<sensor type="gpu_ray" name="head_hokuyo_sensor">
			<pose>0 0 0 0 0 0</pose>
			<visualize>false</visualize>
			<update_rate>40</update_rate>
			<ray>
				<scan>
					<horizontal>
						<samples>360</samples>
						<resolution>1</resolution>
						<min_angle>-3.1415926</min_angle>
						<max_angle>3.1415926</max_angle>
					</horizontal>
				</scan>
				<range>
					<min>0.01</min>
					<max>10.0</max>
					<resolution>0.01</resolution>
				</range>
				<noise>
					<type>gaussian</type>
					<!-- Noise parameters based on published spec for Hokuyo laser
               achieving "+-30mm" accuracy at range < 10m.  A mean of 0.0m and
               stddev of 0.01m will put 99.7% of samples within 0.03m of the true
               reading. -->
					<mean>0.0</mean>
					<stddev>0.01</stddev>
				</noise>
			</ray>
			<plugin name="gazebo_ros_head_hokuyo_controller" filename="libgazebo_ros_gpu_laser.so">
				<topicName>/my_robot/laser/scan</topicName>
				<frameName>hokuyo_link</frameName>
			</plugin>
		</sensor>
	</gazebo>
</robot>
